Workbook

Sheet Assumptions
A1: Assumptions
A2: Editable structured inputs. Orange rows are analyst assumptions. Public anchors are documented separately.
A4: Assumption key | B4: Value | C4: Type | D4: Evidence note
A5: meta.company | B5: Replit | C5: Text | D5: Est. unless identified in Source Register
A6: meta.as_of_date | B6: 2026-09-03 | C6: Text | D6: Est. unless identified in Source Register
A7: meta.forecast_date | B7: 2026-12-01 | C7: Text | D7: Est. unless identified in Source Register
A8: meta.currency | B8: USD | C8: Text | D8: Est. unless identified in Source Register
A9: meta.units | B9: USD millions unless noted | C9: Text | D9: Est. unless identified in Source Register
A10: meta.model_version | B10: 1.0 | C10: Text | D10: Est. unless identified in Source Register
A11: transaction.round | B11: Series E | C11: Text | D11: Est. unless identified in Source Register
A12: transaction.total_raise | B12: 1000 | C12: Numeric | D12: Est. unless identified in Source Register
A13: transaction.primary | B13: 800 | C13: Numeric | D13: Est. unless identified in Source Register
A14: transaction.secondary | B14: 200 | C14: Numeric | D14: Est. unless identified in Source Register
A15: transaction.pre_money | B15: 20000 | C15: Numeric | D15: Est. unless identified in Source Register
A16: transaction.prior_round_amount | B16: 400 | C16: Numeric | D16: Est. unless identified in Source Register
A17: transaction.prior_round_valuation | B17: 9000 | C17: Numeric | D17: Est. unless identified in Source Register
A18: transaction.prior_round_date | B18: 2026-03-11 | C18: Text | D18: Est. unless identified in Source Register
A19: years[0] | B19: 2023 | C19: Numeric | D19: Est. unless identified in Source Register
A20: years[1] | B20: 2024 | C20: Numeric | D20: Est. unless identified in Source Register
A21: years[2] | B21: 2025 | C21: Numeric | D21: Est. unless identified in Source Register
A22: years[3] | B22: 2026 | C22: Numeric | D22: Est. unless identified in Source Register
A23: years[4] | B23: 2027 | C23: Numeric | D23: Est. unless identified in Source Register
A24: years[5] | B24: 2028 | C24: Numeric | D24: Est. unless identified in Source Register
A25: years[6] | B25: 2029 | C25: Numeric | D25: Est. unless identified in Source Register
A26: years[7] | B26: 2030 | C26: Numeric | D26: Est. unless identified in Source Register
A27: years[8] | B27: 2031 | C27: Numeric | D27: Est. unless identified in Source Register
A28: financials.revenue_by_segment.individual[0] | B28: 10 | C28: Numeric | D28: Est. unless identified in Source Register
A29: financials.revenue_by_segment.individual[1] | B29: 15 | C29: Numeric | D29: Est. unless identified in Source Register
A30: financials.revenue_by_segment.individual[2] | B30: 95 | C30: Numeric | D30: Est. unless identified in Source Register
... A257: unit_economics.compute_cost_per_successful_build_index[4] | B257: 35 | C257: Numeric | D257: Est. unless identified in Source Register
A258: pipeline.as_of | B258: 2026-Q3 | C258: Text | D258: Est. unless identified in Source Register
A259: pipeline.qualified_pipeline | B259: 880 | C259: Numeric | D259: Est. unless identified in Source Register
A260: pipeline.late_stage_pipeline | B260: 510 | C260: Numeric | D260: Est. unless identified in Source Register
A261: pipeline.weighted_pipeline | B261: 310 | C261: Numeric | D261: Est. unless identified in Source Register
A262: pipeline.next_12m_new_arr_target | B262: 260 | C262: Numeric | D262: Est. unless identified in Source Register
A263: pipeline.coverage | B263: 3.4 | C263: Numeric | D263: Est. unless identified in Source Register
A264: pipeline.win_rate | B264: 0.24 | C264: Numeric | D264: Est. unless identified in Source Register
A265: pipeline.median_sales_cycle_days | B265: 78 | C265: Numeric | D265: Est. unless identified in Source Register
A266: pipeline.quota_attainment | B266: 0.64 | C266: Numeric | D266: Est. unless identified in Source Register
A267: pipeline.fully_ramped_reps | B267: 96 | C267: Numeric | D267: Est. unless identified in Source Register
...

Sheet Visuals
A1: Visuals
A2: Charts use the same data as the P&L, cash flow, balance sheet, and operating schedules.
A42: Year | B42: Individual | C42: Enterprise | D42: Agent use and hosting | J42: Use | K42: Model training and infrastructure | L42: Enterprise expansion | M42: User growth | N42: International expansion | O42: Talent and research | P42: Execution reserve
A43: 2026E | B43: 300 | C43: 160 | D43: 190 | J43: Primary | K43: 220 | L43: 160 | M43: 140 | N43: 120 | O43: 120 | P43: 40
A44: 2027E | B44: 500 | C44: 360 | D44: 380
A45: 2028E | B45: 700 | C45: 650 | D45: 700
A46: 2029E | B46: 880 | C46: 950 | D46: 1170
A47: 2030E | B47: 1050 | C47: 1300 | D47: 1750
A48: 2031E | B48: 1200 | C48: 1650 | D48: 2400
A52: Month | B52: Base with Series E | C52: Downside with Series E | D52: No Series E | E52: Minimum cash
A53: Oct-26 | B53: 252.26667 | C53: 252.26667 | D53: 252.26667 | E53: 250
A54: Nov-26 | B54: 1000.9333 | C54: 1000.9333 | D54: 230.93333 | E54: 250
A55: Dec-26 | B55: 979.6 | C55: 979.6 | E55: 250
A56: Jan-27 | B56: 975.78333 | C56: 965.07533 | E56: 250
A57: Feb-27 | B57: 971.96667 | C57: 950.55067 | E57: 250
A58: Mar-27 | B58: 968.15 | C58: 936.026 | E58: 250
A59: Apr-27 | B59: 964.33333 | C59: 921.50133 | E59: 250
A60: May-27 | B60: 960.51667 | C60: 906.97667 | E60: 250
A61: Jun-27 | B61: 956.7 | C61: 892.452 | E61: 250
A62: Jul-27 | B62: 952.88333 | C62: 877.92733 | E62: 250
A63: Aug-27 | B63: 949.06667 | C63: 863.40267 | E63: 250
A64: Sep-27 | B64: 945.25 | C64: 848.878 | E64: 250
A65: Oct-27 | B65: 941.43333 | C65: 834.35333 | E65: 250
A66: Nov-27 | B66: 937.61667 | C66: 819.82867 | E66: 250
... A100: Sep-30 | B100: 2702.3 | C100: 902.209 | E100: 250

Sheet P&L
A1: P&L
A2: Income statement in $M. All periods are analyst estimates.
A4: Metric | B4: 2025 | C4: 2026 | D4: 2027 | E4: 2028 | F4: 2029 | G4: 2030 | H4: 2031
A5: Revenue | B5: 170 | C5: 650 | D5: 1240 | E5: 2050 | F5: 3000 | G5: 4100 | H5: 5250
A6: Growth | B6: 5.0714286 | C6: 2.8235294 | D6: 0.90769231 | E6: 0.65322581 | F6: 0.46341463 | G6: 0.36666667 | H6: 0.2804878
A7: Cost of revenue | B7: 122.4 | C7: 351 | D7: 520.8 | E7: 697 | F7: 870 | G7: 1066 | H7: 1260
A8: Gross profit | B8: 47.6 | C8: 299 | D8: 719.2 | E8: 1353 | F8: 2130 | G8: 3034 | H8: 3990
A9: Gross margin | B9: 0.28 | C9: 0.46 | D9: 0.58 | E9: 0.66 | F9: 0.71 | G9: 0.74 | H9: 0.76
A10: R&D | B10: 140 | C10: 300 | D10: 380 | E10: 500 | F10: 650 | G10: 820 | H10: 980
A11: Sales & marketing | B11: 70 | C11: 150 | D11: 250 | E11: 400 | F11: 600 | G11: 820 | H11: 1030
A12: G&A | B12: 45 | C12: 80 | D12: 110 | E12: 160 | F12: 220 | G12: 290 | H12: 360
A13: Operating income | B13: -207.4 | C13: -231 | D13: -20.8 | E13: 293 | F13: 660 | G13: 1104 | H13: 1620
A14: Operating margin | B14: -1.22 | C14: -0.35538462 | D14: -0.016774194 | E14: 0.14292683 | F14: 0.22 | G14: 0.26926829 | H14: 0.30857143
A15: Net income | B15: -207.4 | C15: -231 | D15: -20.8 | E15: 293 | F15: 660 | G15: 1104 | H15: 1620
A16: Stock compensation included in expenses | B16: 28 | C16: 65 | D16: 95 | E16: 130 | F16: 170 | G16: 220 | H16: 275

Sheet Cash Flow
A1: Cash Flow
A2: Annual cash flow and monthly cash runway in $M.
A4: Annual cash flow | B4: 2025 | C4: 2026 | D4: 2027 | E4: 2028 | F4: 2029 | G4: 2030 | H4: 2031
A5: Net income | B5: ='P&L'!B15 -> -207.4 | C5: ='P&L'!C15 -> -231 | D5: ='P&L'!D15 -> -20.8 | E5: ='P&L'!E15 -> 293 | F5: ='P&L'!F15 -> 660 | G5: ='P&L'!G15 -> 1104 | H5: ='P&L'!H15 -> 1620
A6: Stock compensation | B6: ='P&L'!B16 -> 28 | C6: ='P&L'!C16 -> 65 | D6: ='P&L'!D16 -> 95 | E6: ='P&L'!E16 -> 130 | F6: ='P&L'!F16 -> 170 | G6: ='P&L'!G16 -> 220 | H6: ='P&L'!H16 -> 275
A7: Change in working capital | B7: -10 | C7: -20 | D7: -30 | E7: -35 | F7: -40 | G7: -50 | H7: -60
A8: Cash from operations | B8: =B5+B6+B7 -> -189.4 | C8: =C5+C6+C7 -> -186 | D8: =D5+D6+D7 -> 44.2 | E8: =E5+E6+E7 -> 388 | F8: =F5+F6+F7 -> 790 | G8: =G5+G6+G7 -> 1274 | H8: =H5+H6+H7 -> 1835
A9: Capital expenditures | B9: -35 | C9: -70 | D9: -90 | E9: -110 | F9: -135 | G9: -160 | H9: -190
A10: Free cash flow | B10: =B8+B9 -> -224.4 | C10: =C8+C9 -> -256 | D10: =D8+D9 -> -45.8 | E10: =E8+E9 -> 278 | F10: =F8+F9 -> 655 | G10: =G8+G9 -> 1114 | H10: =H8+H9 -> 1645
A11: Prior equity financing | B11: 250 | C11: 400 | D11: 0 | E11: 0 | F11: 0 | G11: 0 | H11: 0
A12: Series E primary | B12: 0 | C12: 800 | D12: 0 | E12: 0 | F12: 0 | G12: 0 | H12: 0
A13: Financing fees | B13: 0 | C13: -30 | D13: 0 | E13: 0 | F13: 0 | G13: 0 | H13: 0
A14: Net change in cash | B14: =B10+B11+B12+B13 -> 25.6 | C14: =C10+C11+C12+C13 -> 914 | D14: =D10+D11+D12+D13 -> -45.8 | E14: =E10+E11+E12+E13 -> 278 | F14: =F10+F11+F12+F13 -> 655 | G14: =G10+G11+G12+G13 -> 1114 | H14: =H10+H11+H12+H13 -> 1645
A15: Beginning cash | B15: 40 | C15: =B16 -> 65.6 | D15: =C16 -> 979.6 | E15: =D16 -> 933.8 | F15: =E16 -> 1211.8 | G15: =F16 -> 1866.8 | H15: =G16 -> 2980.8
A16: Ending cash | B16: =B15+B14 -> 65.6 | C16: =C15+C14 -> 979.6 | D16: =D15+D14 -> 933.8 | E16: =E15+E14 -> 1211.8 | F16: =F15+F14 -> 1866.8 | G16: =G15+G14 -> 2980.8 | H16: =H15+H14 -> 4625.8
A19: Cash summary | B19: Value | C19: Evidence
A20: Cash at September 2026 | B20: 273.6 | C20: Est.
A21: Minimum operating cash | B21: 250 | C21: Est.
A22: Series E close | B22: 46356 | C22: Est.
A23: Net primary proceeds | B23: 770 | C23: Derived
A24: Cash falls below minimum without Series E | B24: 46356 | C24: Derived
A25: IPO target | B25: 47756 | C25: Est.
A26: Cash at IPO in base case | B26: 2702.3 | C26: Derived
A27: Cash at IPO in downside case | B27: 902.209 | C27: Derived
A28: Next equity need | B28: None before IPO in the base case | C28: Derived
A31: Month | B31: Beginning cash | C31: Revenue | D31: Gross profit | E31: Operating expenses | F31: Adjusted operating income | G31: Stock compensation | H31: Capital expenditures | I31: Working capital change | J31: Free cash flow | K31: Series E primary | L31: Financing fees | M31: Ending cash | N31: Ending cash without Series E | O31: Downside ending cash | P31: Minimum cash | Q31: Milestone
A32: 46326 | B32: 273.6 | C32: 54.166667 | D32: 24.916667 | E32: 44.166667 | F32: -19.25 | G32: 5.4166667 | H32: 5.8333333 | I32: 1.6666667 | J32: -21.333333 | K32: 0 | L32: 0 | M32: 252.26667 | N32: 252.26667 | O32: 252.26667 | P32: 250
A33: 46356 | B33: 252.26667 | C33: 54.166667 | D33: 24.916667 | E33: 44.166667 | F33: -19.25 | G33: 5.4166667 | H33: 5.8333333 | I33: 1.6666667 | J33: -21.333333 | K33: 800 | L33: 30 | M33: 1000.9333 | N33: 230.93333 | O33: 1000.9333 | P33: 250 | Q33: Series E close | No-Series-E cash below minimum
A34: 46387 | B34: 1000.9333 | C34: 54.166667 | D34: 24.916667 | E34: 44.166667 | F34: -19.25 | G34: 5.4166667 | H34: 5.8333333 | I34: 1.6666667 | J34: -21.333333 | K34: 0 | L34: 0 | M34: 979.6 | N34: 209.6 | O34: 979.6 | P34: 250
A35: 46418 | B35: 979.6 | C35: 103.33333 | D35: 59.933333 | E35: 61.666667 | F35: -1.7333333 | G35: 7.9166667 | H35: 7.5 | I35: 2.5 | J35: -3.8166667 | K35: 0 | L35: 0 | M35: 975.78333 | N35: 205.78333 | O35: 965.07533 | P35: 250
A36: 46446 | B36: 975.78333 | C36: 103.33333 | D36: 59.933333 | E36: 61.666667 | F36: -1.7333333 | G36: 7.9166667 | H36: 7.5 | I36: 2.5 | J36: -3.8166667 | K36: 0 | L36: 0 | M36: 971.96667 | N36: 201.96667 | O36: 950.55067 | P36: 250
A37: 46477 | B37: 971.96667 | C37: 103.33333 | D37: 59.933333 | E37: 61.666667 | F37: -1.7333333 | G37: 7.9166667 | H37: 7.5 | I37: 2.5 | J37: -3.8166667 | K37: 0 | L37: 0 | M37: 968.15 | N37: 198.15 | O37: 936.026 | P37: 250
A38: 46507 | B38: 968.15 | C38: 103.33333 | D38: 59.933333 | E38: 61.666667 | F38: -1.7333333 | G38: 7.9166667 | H38: 7.5 | I38: 2.5 | J38: -3.8166667 | K38: 0 | L38: 0 | M38: 964.33333 | N38: 194.33333 | O38: 921.50133 | P38: 250
A39: 46538 | B39: 964.33333 | C39: 103.33333 | D39: 59.933333 | E39: 61.666667 | F39: -1.7333333 | G39: 7.9166667 | H39: 7.5 | I39: 2.5 | J39: -3.8166667 | K39: 0 | L39: 0 | M39: 960.51667 | N39: 190.51667 | O39: 906.97667 | P39: 250
A40: 46568 | B40: 960.51667 | C40: 103.33333 | D40: 59.933333 | E40: 61.666667 | F40: -1.7333333 | G40: 7.9166667 | H40: 7.5 | I40: 2.5 | J40: -3.8166667 | K40: 0 | L40: 0 | M40: 956.7 | N40: 186.7 | O40: 892.452 | P40: 250
A41: 46599 | B41: 956.7 | C41: 103.33333 | D41: 59.933333 | E41: 61.666667 | F41: -1.7333333 | G41: 7.9166667 | H41: 7.5 | I41: 2.5 | J41: -3.8166667 | K41: 0 | L41: 0 | M41: 952.88333 | N41: 182.88333 | O41: 877.92733 | P41: 250
A42: 46630 | B42: 952.88333 | C42: 103.33333 | D42: 59.933333 | E42: 61.666667 | F42: -1.7333333 | G42: 7.9166667 | H42: 7.5 | I42: 2.5 | J42: -3.8166667 | K42: 0 | L42: 0 | M42: 949.06667 | N42: 179.06667 | O42: 863.40267 | P42: 250
A43: 46660 | B43: 949.06667 | C43: 103.33333 | D43: 59.933333 | E43: 61.666667 | F43: -1.7333333 | G43: 7.9166667 | H43: 7.5 | I43: 2.5 | J43: -3.8166667 | K43: 0 | L43: 0 | M43: 945.25 | N43: 175.25 | O43: 848.878 | P43: 250
A44: 46691 | B44: 945.25 | C44: 103.33333 | D44: 59.933333 | E44: 61.666667 | F44: -1.7333333 | G44: 7.9166667 | H44: 7.5 | I44: 2.5 | J44: -3.8166667 | K44: 0 | L44: 0 | M44: 941.43333 | N44: 171.43333 | O44: 834.35333 | P44: 250
A45: 46721 | B45: 941.43333 | C45: 103.33333 | D45: 59.933333 | E45: 61.666667 | F45: -1.7333333 | G45: 7.9166667 | H45: 7.5 | I45: 2.5 | J45: -3.8166667 | K45: 0 | L45: 0 | M45: 937.61667 | N45: 167.61667 | O45: 819.82867 | P45: 250
...

Sheet Balance Sheet
A1: Balance Sheet
A2: Simplified balance sheet in $M. Cash links to the cash-flow statement.
A4: Balance sheet | B4: 2025 | C4: 2026 | D4: 2027 | E4: 2028 | F4: 2029 | G4: 2030 | H4: 2031
A5: Cash | B5: ='Cash Flow'!B16 -> 65.6 | C5: ='Cash Flow'!C16 -> 979.6 | D5: ='Cash Flow'!D16 -> 933.8 | E5: ='Cash Flow'!E16 -> 1211.8 | F5: ='Cash Flow'!F16 -> 1866.8 | G5: ='Cash Flow'!G16 -> 2980.8 | H5: ='Cash Flow'!H16 -> 4625.8
A6: Accounts receivable | B6: 17 | C6: 65 | D6: 124 | E6: 205 | F6: 300 | G6: 410 | H6: 525
A7: Other current assets | B7: 6.8 | C7: 26 | D7: 49.6 | E7: 82 | F7: 120 | G7: 164 | H7: 210
A8: Property and equipment | B8: 65 | C8: 135 | D8: 225 | E8: 335 | F8: 470 | G8: 630 | H8: 820
A9: Other assets | B9: 5.1 | C9: 19.5 | D9: 37.2 | E9: 61.5 | F9: 90 | G9: 123 | H9: 157.5
A10: Total assets | B10: =B5+B6+B7+B8+B9 -> 159.5 | C10: =C5+C6+C7+C8+C9 -> 1225.1 | D10: =D5+D6+D7+D8+D9 -> 1369.6 | E10: =E5+E6+E7+E8+E9 -> 1895.3 | F10: =F5+F6+F7+F8+F9 -> 2846.8 | G10: =G5+G6+G7+G8+G9 -> 4307.8 | H10: =H5+H6+H7+H8+H9 -> 6338.3
A11: Accounts payable | B11: 6.12 | C11: 17.55 | D11: 26.04 | E11: 34.85 | F11: 43.5 | G11: 53.3 | H11: 63
A12: Accrued expenses | B12: 2.58 | C12: 23.95 | D12: 50.36 | E12: 95.65 | F12: 151.5 | G12: 212.7 | H12: 269.5
A13: Deferred revenue | B13: 3.4 | C13: 13 | D13: 24.8 | E13: 41 | F13: 60 | G13: 82 | H13: 105
A14: Other liabilities | B14: 1.7 | C14: 6.5 | D14: 12.4 | E14: 20.5 | F14: 30 | G14: 41 | H14: 52.5
A15: Debt | B15: 0 | C15: 0 | D15: 0 | E15: 0 | F15: 0 | G15: 0 | H15: 0
A16: Total liabilities | B16: =B11+B12+B13+B14+B15 -> 13.8 | C16: =C11+C12+C13+C14+C15 -> 61 | D16: =D11+D12+D13+D14+D15 -> 113.6 | E16: =E11+E12+E13+E14+E15 -> 192 | F16: =F11+F12+F13+F14+F15 -> 285 | G16: =G11+G12+G13+G14+G15 -> 389 | H16: =H11+H12+H13+H14+H15 -> 490
A17: Total equity | B17: =B10-B16 -> 145.7 | C17: =C10-C16 -> 1164.1 | D17: =D10-D16 -> 1256 | E17: =E10-E16 -> 1703.3 | F17: =F10-F16 -> 2561.8 | G17: =G10-G16 -> 3918.8 | H17: =H10-H16 -> 5848.3
A18: Liabilities and equity | B18: =B16+B17 -> 159.5 | C18: =C16+C17 -> 1225.1 | D18: =D16+D17 -> 1369.6 | E18: =E16+E17 -> 1895.3 | F18: =F16+F17 -> 2846.8 | G18: =G16+G17 -> 4307.8 | H18: =H16+H17 -> 6338.3
A19: Balance check | B19: =B10-B18 -> 0 | C19: =C10-C18 -> 0 | D19: =D10-D18 -> 0 | E19: =E10-E18 -> 0 | F19: =F10-F18 -> 0 | G19: =G10-G18 -> 0 | H19: =H10-H18 -> 0

Sheet Read Me
A1: Replit Series E Sourcebook
A2: Public evidence, analyst assumptions, operating model, scenarios, and slide-level reconciliation.
A4: Important
A5: This workbook is an illustrative financing model prepared from public information. It is not Replit confidential information, a forecast issued by Replit, or investment advice.
A8: Evidence class | B8: Meaning | C8: Workbook color
A9: Public fact | B9: Direct or attributable public disclosure | C9: Light orange
A10: Derived | B10: Arithmetic based on public facts | C10: Gray
A11: Est. | B11: Analyst estimate based on stated assumptions | C11: Orange
A12: Management target | B12: Forward-looking goal stated by management | C12: Dark orange
A15: Transaction metric | B15: Value | C15: Evidence
A16: Round | B16: Series E | C16: Illustrative
A17: Total raise | B17: 1000 | C17: Illustrative
A18: Primary capital | B18: 800 | C18: Illustrative
A19: Secondary liquidity | B19: 200 | C19: Illustrative
A20: Pre-money valuation | B20: 20000 | C20: Illustrative
A21: Post-money valuation | B21: 20800 | C21: Derived
A22: Primary dilution | B22: 0.038461538 | C22: Derived
A23: Total buyer ownership | B23: 0.048076923 | C23: Derived

Sheet Source Register
A1: Source Register
A2: Canonical public and modeled sources. URLs are retained for diligence and slide reconciliation.
A4: Source ID | B4: Publisher | C4: Title | D4: Publication date | E4: Access date | F4: Quality | G4: Evidence class | H4: URL
A5: RPL-D-2026 | B5: Replit | C5: The Future is Actually Very Human | D5: 2026-03-11 | E5: 2026-09-03 | F5: primary | G5: public | H5: https://replit.com/blog/replit-raises-400-million-dollars
A6: RPL-C-2025 | B6: Replit | C6: Replit Raises $250M in Series C Funding | D6: 2025-09-10 | E6: 2026-09-03 | F6: primary | G6: public | H6: https://replit.com/news/funding-announcement-series-c
A7: RPL-AGENT4-2026 | B7: Replit | C7: Introducing Replit Agent 4: Built for Creativity | D7: 2026-03-11 | E7: 2026-09-03 | F7: primary | G7: public | H7: https://replit.com/blog/introducing-agent-4-built-for-creativity
A8: RPL-ENT-2026 | B8: Replit | C8: Replit Enterprise | E8: 2026-09-03 | F8: primary | G8: public | H8: https://replit.com/enterprise
A9: RPL-CUST-UKG | B9: Replit | C9: The Future is Actually Very Human | D9: 2026-03-11 | E9: 2026-09-03 | F9: primary | G9: public | H9: https://replit.com/blog/replit-raises-400-million-dollars
A10: RPL-ENT-DOC-2026 | B10: Replit | C10: Replit Enterprise | E10: 2026-09-03 | F10: primary | G10: public | H10: https://docs.replit.com/billing/plans/replit-enterprise
A11: RPL-SEC-DOC-2026 | B11: Replit | C11: Information Security | E11: 2026-09-03 | F11: primary | G11: public | H11: https://docs.replit.com/teams/information-security/overview
A12: RPL-REVIEW-2025 | B12: Replit | C12: 2025: Replit in Review | D12: 2025-12-18 | E12: 2026-09-03 | F12: primary | G12: public | H12: https://replit.com/blog/2025-replit-in-review
A13: RPL-SECURITY-AGENT | B13: Replit | C13: Meet Replit Security Agent | E13: 2026-09-03 | F13: primary | G13: public | H13: https://replit.com/blog/meet-replit-security-agent
A14: RPL-PRICING-2026 | B14: Replit | C14: Pricing and Plans | E14: 2026-09-03 | F14: primary | G14: public | H14: https://replit.com/pricing
A15: RPL-GOOGLE-2026 | B15: Replit | C15: Build anything. With Google. | E15: 2026-09-03 | F15: primary | G15: public | H15: https://replit.com/partners/google
A16: RPL-MICROSOFT-2026 | B16: Replit | C16: Replit × Microsoft Fabric | E16: 2026-09-03 | F16: primary | G16: public | H16: https://replit.com/partners/microsoft
A17: RPL-LEADERSHIP-AMJAD | B17: Replit | C17: Amjad Masad | D17: 2023-10-05 | E17: 2026-09-03 | F17: primary | G17: public | H17: https://replit.com/blog/author/amjad-masad
A18: RPL-BRAND | B18: Replit | C18: Replit Brand | E18: 2026-09-03 | F18: primary | G18: public | H18: https://replit.com/brand
A19: TECHCRUNCH-D-2026 | B19: TechCrunch | C19: Replit snags $9B valuation 6 months after hitting $3B | D19: 2026-03-11 | E19: 2026-09-03 | F19: major_press | G19: public | H19: https://techcrunch.com/2026/03/11/replit-snags-9b-valuation-6-months-after-hitting-3b/
A20: SACRA-2025 | B20: Sacra | C20: Replit at $253M ARR growing 2,352% YoY | E20: 2026-09-03 | F20: third_party_analysis | G20: estimate | H20: https://sacra.com/research/replit-at-253m-arr-growing-2352-yoy/
A21: GITHUB-OCTOVERSE-2025 | B21: GitHub | C21: Octoverse 2025 | D21: 2025-11-01 | E21: 2026-09-03 | F21: primary_research | G21: public | H21: https://github.blog/news-insights/octoverse/
A22: EVANS-DEVELOPERS-2024 | B22: Evans Data Corporation | C22: Global Developer Population and Demographic Study | D22: 2024-07-29 | E22: 2026-09-03 | F22: primary_research | G22: public | H22: https://evansdata.com/press/viewRelease.php?pressID=365
A23: IDC-DEVELOPER-2024 | B23: IDC | C23: Worldwide Developer Population Forecast | D23: 2025 | E23: 2026-09-03 | F23: market_research | G23: public | H23: https://my.idc.com/getdoc.jsp?containerId=US53592125
A24: IDC-KNOWLEDGE-2025 | B24: IDC | C24: Worldwide Knowledge Worker Forecast | D24: 2025 | E24: 2026-09-03 | F24: market_research | G24: public | H24: https://my.idc.com/getdoc.jsp?containerId=US53782225
A25: MS-WORK-TREND-2024 | B25: Microsoft and LinkedIn | C25: AI at work is here. Now comes the hard part. | D25: 2024-05-08 | E25: 2026-09-03 | F25: primary_research | G25: public | H25: https://www.microsoft.com/en-us/worklab/work-trend-index/ai-at-work-is-here-now-comes-the-hard-part
A26: GARTNER-AI-CODE-2024 | B26: Gartner | C26: Gartner Says 75% of Enterprise Software Engineers Will Use AI Code Assistants by 2028 | D26: 2024-04-11 | E26: 2026-09-03 | F26: market_research | G26: public | H26: https://www.gartner.com/en/newsroom/press-releases/2024-04-11-gartner-says-75-percent-of-enterprise-software-engineers-will-use-ai-code-assistants-by-2028
A27: GARTNER-CLOUD-2024 | B27: Gartner | C27: Worldwide Public Cloud End-User Spending to Total $723.4 Billion in 2025 | D27: 2024-11-19 | E27: 2026-09-03 | F27: market_research | G27: public | H27: https://www.gartner.com/en/newsroom/press-releases/2024-11-19-gartner-forecasts-worldwide-public-cloud-end-user-spending-to-total-723-billion-dollars-in-2025
A28: GVR-AI-CODE-2024 | B28: Grand View Research | C28: AI Code Tools Market Size and Share Report, 2024–2030 | D28: 2024 | E28: 2026-09-03 | F28: market_research | G28: public | H28: https://www.grandviewresearch.com/industry-analysis/ai-code-tools-market-report
A29: CURSOR-D-2025 | B29: Cursor | C29: Cursor Series D | D29: 2025-11-13 | E29: 2026-09-03 | F29: primary | G29: public | H29: https://cursor.com/blog/series-d
A30: ANTHROPIC-CLAUDE-CODE-2025 | B30: Anthropic | C30: Anthropic acquires Bun as Claude Code reaches $1B milestone | D30: 2025-12-03 | E30: 2026-09-03 | F30: primary | G30: public | H30: https://www.anthropic.com/news/anthropic-acquires-bun-as-claude-code-reaches-usd1b-milestone
A31: LOVABLE-B-2025 | B31: Lovable | C31: Series B | D31: 2025-12-18 | E31: 2026-09-03 | F31: primary | G31: public | H31: https://lovable.dev/blog/series-b
A32: MSFT-FY25-Q4 | B32: Microsoft | C32: FY 2025 Q4 Earnings | D32: 2025-07-30 | E32: 2026-09-03 | F32: public_company | G32: public | H32: https://www.microsoft.com/en-us/investor/events/fy-2025/earnings-fy-2025-q4
A33: COGNITION-WINDSURF | B33: Cognition | C33: Cognition and Windsurf | D33: 2025-07-14 | E33: 2026-09-03 | F33: primary | G33: public | H33: https://cognition.com/blog/windsurf
A34: V0-DOCS | B34: Vercel | C34: v0 Documentation | E34: 2026-09-03 | F34: primary | G34: public | H34: https://v0.app/docs.md
A35: COMP-CRM-2026 | B35: Stock Analysis | C35: Salesforce Statistics | E35: 2026-09-03 | F35: market_data | G35: public | H35: https://stockanalysis.com/stocks/crm/statistics/
A36: COMP-NOW-2026 | B36: Stock Analysis | C36: ServiceNow Statistics | E36: 2026-09-03 | F36: market_data | G36: public | H36: https://stockanalysis.com/stocks/now/statistics/
A37: COMP-MSFT-2026 | B37: Stock Analysis | C37: Microsoft Statistics | E37: 2026-09-03 | F37: market_data | G37: public | H37: https://stockanalysis.com/stocks/msft/statistics/
A38: COMP-TEAM-2026 | B38: Stock Analysis | C38: Atlassian Statistics | E38: 2026-09-03 | F38: market_data | G38: public | H38: https://stockanalysis.com/stocks/team/statistics/
A39: COMP-GTLB-2026 | B39: Stock Analysis | C39: GitLab Statistics | E39: 2026-09-03 | F39: market_data | G39: public | H39: https://stockanalysis.com/stocks/gtlb/statistics/
A40: COMP-NET-2026 | B40: Stock Analysis | C40: Cloudflare Statistics | E40: 2026-09-03 | F40: market_data | G40: public | H40: https://stockanalysis.com/stocks/net/statistics/
A41: MODEL-ESTIMATES | B41: Analyst model | C41: Replit Series E operating model | D41: 2026-09-03 | E41: 2026-09-03 | F41: modeled | G41: estimate

Sheet Public Facts
A1: Public Facts
A2: Claim-level evidence extracted from the source register. Modeled claims remain visibly separate.
A4: Source ID | B4: Publisher | C4: Title | D4: Claim | E4: Publication date | F4: Access date | G4: Quality | H4: Evidence class | I4: URL
A5: RPL-D-2026 | B5: Replit | C5: The Future is Actually Very Human | D5: $400M financing at a $9B valuation | E5: 2026-03-11 | F5: 2026-09-03 | G5: primary | H5: public | I5: https://replit.com/blog/replit-raises-400-million-dollars
A6: RPL-D-2026 | B6: Replit | C6: The Future is Actually Very Human | D6: More than 50M users | E6: 2026-03-11 | F6: 2026-09-03 | G6: primary | H6: public | I6: https://replit.com/blog/replit-raises-400-million-dollars
A7: RPL-D-2026 | B7: Replit | C7: The Future is Actually Very Human | D7: Users from 85% of the Fortune 500 | E7: 2026-03-11 | F7: 2026-09-03 | G7: primary | H7: public | I7: https://replit.com/blog/replit-raises-400-million-dollars
A8: RPL-D-2026 | B8: Replit | C8: The Future is Actually Very Human | D8: Management target of $1B run-rate revenue by year-end 2026 | E8: 2026-03-11 | F8: 2026-09-03 | G8: primary | H8: public | I8: https://replit.com/blog/replit-raises-400-million-dollars
A9: RPL-D-2026 | B9: Replit | C9: The Future is Actually Very Human | D9: Global expansion focus across Europe, Asia, and the Middle East | E9: 2026-03-11 | F9: 2026-09-03 | G9: primary | H9: public | I9: https://replit.com/blog/replit-raises-400-million-dollars
A10: RPL-D-2026 | B10: Replit | C10: The Future is Actually Very Human | D10: Agent 4 is described as 10x faster than Agent 3 | E10: 2026-03-11 | F10: 2026-09-03 | G10: primary | H10: public | I10: https://replit.com/blog/replit-raises-400-million-dollars
A11: RPL-C-2025 | B11: Replit | C11: Replit Raises $250M in Series C Funding | D11: $250M Series C financing at a $3B valuation | E11: 2025-09-10 | F11: 2026-09-03 | G11: primary | H11: public | I11: https://replit.com/news/funding-announcement-series-c
A12: RPL-AGENT4-2026 | B12: Replit | C12: Introducing Replit Agent 4: Built for Creativity | D12: Agent 4 is described as 10x faster than Agent 3 | E12: 2026-03-11 | F12: 2026-09-03 | G12: primary | H12: public | I12: https://replit.com/blog/introducing-agent-4-built-for-creativity
A13: RPL-AGENT4-2026 | B13: Replit | C13: Introducing Replit Agent 4: Built for Creativity | D13: Parallel agents and a task-based workflow | E13: 2026-03-11 | F13: 2026-09-03 | G13: primary | H13: public | I13: https://replit.com/blog/introducing-agent-4-built-for-creativity
A14: RPL-AGENT4-2026 | B14: Replit | C14: Introducing Replit Agent 4: Built for Creativity | D14: Design, software, slides, videos, and tools in a unified project | E14: 2026-03-11 | F14: 2026-09-03 | G14: primary | H14: public | I14: https://replit.com/blog/introducing-agent-4-built-for-creativity
A15: RPL-ENT-2026 | B15: Replit | C15: Replit Enterprise | D15: Named enterprise references and product positioning | F15: 2026-09-03 | G15: primary | H15: public | I15: https://replit.com/enterprise
A16: RPL-CUST-UKG | B16: Replit | C16: The Future is Actually Very Human | D16: UKG has more than 16,000 employees | E16: 2026-03-11 | F16: 2026-09-03 | G16: primary | H16: public | I16: https://replit.com/blog/replit-raises-400-million-dollars
A17: RPL-CUST-UKG | B17: Replit | C17: The Future is Actually Very Human | D17: UKG reported a 400% increase in its ability to gather product-led, customer-driven feedback before engineering investment | E17: 2026-03-11 | F17: 2026-09-03 | G17: primary | H17: public | I17: https://replit.com/blog/replit-raises-400-million-dollars
A18: RPL-CUST-UKG | B18: Replit | C18: The Future is Actually Very Human | D18: UKG uses Replit for rapid prototyping, product development, and internal tools | E18: 2026-03-11 | F18: 2026-09-03 | G18: primary | H18: public | I18: https://replit.com/blog/replit-raises-400-million-dollars
A19: RPL-ENT-DOC-2026 | B19: Replit | C19: Replit Enterprise | D19: Unlimited seats and self-serve enterprise upgrade | F19: 2026-09-03 | G19: primary | H19: public | I19: https://docs.replit.com/billing/plans/replit-enterprise
A20: RPL-ENT-DOC-2026 | B20: Replit | C20: Replit Enterprise | D20: Annual credit commitments and pay-as-you-go usage | F20: 2026-09-03 | G20: primary | H20: public | I20: https://docs.replit.com/billing/plans/replit-enterprise
A21: RPL-ENT-DOC-2026 | B21: Replit | C21: Replit Enterprise | D21: SSO, SAML, SCIM, RBAC, audit logging, and deployment controls | F21: 2026-09-03 | G21: primary | H21: public | I21: https://docs.replit.com/billing/plans/replit-enterprise
A22: RPL-ENT-DOC-2026 | B22: Replit | C22: Replit Enterprise | D22: Databricks, BigQuery, Microsoft Fabric, Hex, and Snowflake integrations | F22: 2026-09-03 | G22: primary | H22: public | I22: https://docs.replit.com/billing/plans/replit-enterprise
A23: RPL-SEC-DOC-2026 | B23: Replit | C23: Information Security | D23: SOC 2 Type 2 attestation | F23: 2026-09-03 | G23: primary | H23: public | I23: https://docs.replit.com/teams/information-security/overview
A24: RPL-SEC-DOC-2026 | B24: Replit | C24: Information Security | D24: TLS 1.2+ in transit and AES-256 at rest | F24: 2026-09-03 | G24: primary | H24: public | I24: https://docs.replit.com/teams/information-security/overview
A25: RPL-SEC-DOC-2026 | B25: Replit | C25: Information Security | D25: Private-network architecture and WAF protection | F25: 2026-09-03 | G25: primary | H25: public | I25: https://docs.replit.com/teams/information-security/overview
A26: RPL-SEC-DOC-2026 | B26: Replit | C26: Information Security | D26: US hosting with an optional India region | F26: 2026-09-03 | G26: primary | H26: public | I26: https://docs.replit.com/teams/information-security/overview
A27: RPL-REVIEW-2025 | B27: Replit | C27: 2025: Replit in Review | D27: SOC 2 Type II with zero exceptions | E27: 2025-12-18 | F27: 2026-09-03 | G27: primary | H27: public | I27: https://replit.com/blog/2025-replit-in-review
A28: RPL-REVIEW-2025 | B28: Replit | C28: 2025: Replit in Review | D28: Enterprise controls and ecosystem progress | E28: 2025-12-18 | F28: 2026-09-03 | G28: primary | H28: public | I28: https://replit.com/blog/2025-replit-in-review
A29: RPL-SECURITY-AGENT | B29: Replit | C29: Meet Replit Security Agent | D29: Agent-assisted security review and remediation workflow | F29: 2026-09-03 | G29: primary | H29: public | I29: https://replit.com/blog/meet-replit-security-agent
A30: RPL-PRICING-2026 | B30: Replit | C30: Pricing and Plans | D30: Free, individual, team, and enterprise monetization structure | F30: 2026-09-03 | G30: primary | H30: public | I30: https://replit.com/pricing
A31: RPL-PRICING-2026 | B31: Replit | C31: Pricing and Plans | D31: Usage credits and enterprise commitment architecture | F31: 2026-09-03 | G31: primary | H31: public | I31: https://replit.com/pricing
A32: RPL-GOOGLE-2026 | B32: Replit | C32: Build anything. With Google. | D32: Gemini models, Google Cloud infrastructure, and Workspace integrations | F32: 2026-09-03 | G32: primary | H32: public | I32: https://replit.com/partners/google
A33: RPL-MICROSOFT-2026 | B33: Replit | C33: Replit × Microsoft Fabric | D33: OneLake, Entra, Purview, and Microsoft Fabric integration | F33: 2026-09-03 | G33: primary | H33: public | I33: https://replit.com/partners/microsoft
A34: RPL-LEADERSHIP-AMJAD | B34: Replit | C34: Amjad Masad | D34: Amjad Masad is Replit's founder and CEO | E34: 2023-10-05 | F34: 2026-09-03 | G34: primary | H34: public | I34: https://replit.com/blog/author/amjad-masad
A35: RPL-BRAND | B35: Replit | C35: Replit Brand | D35: Official Replit visual identity and assets | F35: 2026-09-03 | G35: primary | H35: public | I35: https://replit.com/brand
A36: TECHCRUNCH-D-2026 | B36: TechCrunch | C36: Replit snags $9B valuation 6 months after hitting $3B | D36: Series D context and prior valuation | E36: 2026-03-11 | F36: 2026-09-03 | G36: major_press | H36: public | I36: https://techcrunch.com/2026/03/11/replit-snags-9b-valuation-6-months-after-hitting-3b/
A37: SACRA-2025 | B37: Sacra | C37: Replit at $253M ARR growing 2,352% YoY | D37: Third-party revenue and margin estimates | F37: 2026-09-03 | G37: third_party_analysis | H37: estimate | I37: https://sacra.com/research/replit-at-253m-arr-growing-2352-yoy/
A38: GITHUB-OCTOVERSE-2025 | B38: GitHub | C38: Octoverse 2025 | D38: Global developer and AI coding adoption context | E38: 2025-11-01 | F38: 2026-09-03 | G38: primary_research | H38: public | I38: https://github.blog/news-insights/octoverse/
A39: EVANS-DEVELOPERS-2024 | B39: Evans Data Corporation | C39: Global Developer Population and Demographic Study | D39: 27 million professional developers worldwide | E39: 2024-07-29 | F39: 2026-09-03 | G39: primary_research | H39: public | I39: https://evansdata.com/press/viewRelease.php?pressID=365
A40: IDC-DEVELOPER-2024 | B40: IDC | C40: Worldwide Developer Population Forecast | D40: 40.1 million developers in 2025, projected to reach 59.5 million by 2029 | E40: 2025 | F40: 2026-09-03 | G40: market_research | H40: public | I40: https://my.idc.com/getdoc.jsp?containerId=US53592125
A41: IDC-KNOWLEDGE-2025 | B41: IDC | C41: Worldwide Knowledge Worker Forecast | D41: 888 million knowledge workers in 2025, projected to reach 1.2 billion by 2029 | E41: 2025 | F41: 2026-09-03 | G41: market_research | H41: public | I41: https://my.idc.com/getdoc.jsp?containerId=US53782225
...

Sheet Historical KPIs
A1: Historical KPIs
A2: Public anchors and analyst estimates from 2023 to 2026.
A4: Metric | B4: Units | C4: 2023 | D4: 2024 | E4: 2025 | F4: 2026 | G4: Evidence
A5: Revenue | B5: $M | C5: 16 | D5: 28 | E5: 170 | F5: 650 | G5: Public anchor / Est.
A6: Exit ARR | B6: $M | C6: 20 | D6: 28 | E6: 300 | F6: 1000 | G6: Public anchor / Est.
A7: Registered users | B7: M | C7: 22.5 | D7: 30 | E7: 40 | F7: 50 | G7: Public anchor / Est.
A8: Monthly active builders | B8: M | C8: 2.5 | D8: 3.3 | E8: 6.8 | F8: 11 | G8: Public anchor / Est.
A9: Paid individuals | B9: M | C9: 0.1 | D9: 0.16 | E9: 0.65 | F9: 1.8 | G9: Public anchor / Est.
A10: Enterprise customers | B10: # | C10: 40 | D10: 100 | E10: 400 | F10: 1200 | G10: Public anchor / Est.
A11: Paid conversion | B11: % | C11: 0.04 | D11: 0.048484848 | E11: 0.095588235 | F11: 0.16363636 | G11: Public anchor / Est.
A12: Enterprise GRR | B12: % | C12: 0.85 | D12: 0.88 | E12: 0.9 | F12: 0.92 | G12: Public anchor / Est.
A13: Enterprise NRR | B13: % | C13: 1.15 | D13: 1.2 | E13: 1.3 | F13: 1.38 | G13: Public anchor / Est.
A14: International revenue share | B14: % | C14: 0.25 | D14: 0.28 | E14: 0.32 | F14: 0.36 | G14: Public anchor / Est.

Sheet Revenue Build
A1: Revenue Build
A2: Segment model in $M. The 2023 to 2026 periods are estimated history. The forecast starts in 2027.
A4: Metric | B4: 2023 | C4: 2024 | D4: 2025 | E4: 2026 | F4: 2027 | G4: 2028 | H4: 2029 | I4: 2030 | J4: 2031
A5: Individual | B5: 10 | C5: 15 | D5: 95 | E5: 300 | F5: 500 | G5: 700 | H5: 880 | I5: 1050 | J5: 1200
A6: Enterprise | B6: 3 | C6: 6 | D6: 35 | E6: 160 | F6: 360 | G6: 650 | H6: 950 | I6: 1300 | J6: 1650
A7: Usage & deploy | B7: 3 | C7: 7 | D7: 40 | E7: 190 | F7: 380 | G7: 700 | H7: 1170 | I7: 1750 | J7: 2400
A8: Total revenue | B8: 16 | C8: 28 | D8: 170 | E8: 650 | F8: 1240 | G8: 2050 | H8: 3000 | I8: 4100 | J8: 5250
A9: Year-over-year growth | C9: 0.75 | D9: 5.0714286 | E9: 2.8235294 | F9: 0.90769231 | G9: 0.65322581 | H9: 0.46341463 | I9: 0.36666667 | J9: 0.2804878

Sheet Cohorts & Retention
A1: Cohorts & Retention
A2: Illustrative enterprise ARR cohorts. All values are analyst estimates.
A4: Cohort | B4: Start | C4: Month 12 | D4: Month 24 | E4: Month 36 | F4: Evidence
A5: 2023 | B5: 1 | C5: 1.12 | D5: 1.28 | E5: 1.42 | F5: Est.
A6: 2024 | B6: 1 | C6: 1.22 | D6: 1.48 | E6: 1.7 | F6: Est.
A7: 2025 | B7: 1 | C7: 1.35 | D7: 1.62 | F7: Est.
A8: 2026 | B8: 1 | C8: 1.38 | F8: Est.

Sheet Unit Economics
A1: Unit Economics
A2: Analyst estimates connecting model efficiency, gross margin, acquisition cost, and payback.
A4: Metric | B4: 2025 | C4: 2026 | D4: 2027 | E4: 2028 | F4: 2029 | G4: Evidence
A5: Blended gross margin | B5: 0.28 | C5: 0.46 | D5: 0.58 | E5: 0.66 | F5: 0.71 | G5: Est.
A6: Individual CAC | B6: 55 | C6: 44 | D6: 39 | E6: 35 | F6: 32 | G6: Est.
A7: Individual payback | B7: 9 | C7: 6 | D7: 5 | E7: 4.5 | F7: 4 | G7: Est.
A8: Enterprise CAC | B8: 145 | C8: 120 | D8: 105 | E8: 95 | F8: 90 | G8: Est.
A9: Enterprise payback | B9: 19 | C9: 14 | D9: 12 | E9: 10 | F9: 9 | G9: Est.
A10: Enterprise LTV / CAC | B10: 3.2 | C10: 4.2 | D10: 5 | E10: 5.6 | F10: 6 | G10: Est.
A11: Compute cost / successful build index | B11: 100 | C11: 72 | D11: 54 | E11: 42 | F11: 35 | G11: Est.

Sheet GTM & Pipeline
A1: GTM & Pipeline
A2: Illustrative Q3 2026 enterprise pipeline and sales-capacity assumptions.
A4: Metric | B4: Value | C4: Units | D4: Evidence
A5: Qualified pipeline | B5: 880 | C5: $M | D5: Est.
A6: Late-stage pipeline | B6: 510 | C6: $M | D6: Est.
A7: Weighted pipeline | B7: 310 | C7: $M | D7: Est.
A8: Next-12-month new ARR target | B8: 260 | C8: $M | D8: Est.
A9: Pipeline coverage | B9: 3.4 | C9: x | D9: Est.
A10: Win rate | B10: 0.24 | C10: % | D10: Est.
A11: Median sales cycle | B11: 78 | C11: days | D11: Est.
A12: Quota attainment | B12: 0.64 | C12: % | D12: Est.
A13: Fully ramped reps | B13: 96 | C13: # | D13: Est.
A14: New ARR per ramped rep | B14: 1.2 | C14: $M | D14: Est.
A15: Rep ramp | B15: 6 | C15: months | D15: Est.

Sheet Market Model
A1: Market Model
A2: Bottom-up opportunity sizing. Population and monetization inputs are analyst estimates triangulated to public research.
A4: Segment | B4: Population / workloads (M) | C4: Annual revenue per unit ($) | D4: TAM ($M) | E4: Near-term SAM ($M) | F4: Evidence
A5: Individual creators | B5: 125 | C5: 400 | D5: 50000 | E5: 20000 | F5: Derived / Est.
A6: Enterprise business builders | B6: 200 | C6: 480 | D6: 96000 | E6: 35000 | F6: Derived / Est.
A7: Professional development teams | B7: 45 | C7: 1200 | D7: 54000 | E7: 20000 | F7: Derived / Est.
A8: Agent and runtime workloads | B8: 25 | C8: 2000 | D8: 50000 | E8: 15000 | F8: Derived / Est.
A9: Total | D9: 250000 | E9: 90000 | F9: Derived

Sheet Scenarios
A1: Scenarios
A2: Base, downside, and upside operating outcomes from 2026 to 2031.
A4: Scenario | B4: Metric | C4: 2026 | D4: 2027 | E4: 2028 | F4: 2029 | G4: 2030 | H4: 2031
A5: Downside | B5: Revenue | C5: 650 | D5: 1016.8 | E5: 1496.5 | F5: 2040 | G5: 2706 | H5: 3412.5
A6: Downside | B6: Gross margin | C6: 0.46 | D6: 0.53 | E6: 0.59 | F6: 0.63 | G6: 0.66 | H6: 0.69
A7: Downside | B7: Adjusted operating margin | C7: -0.35538462 | D7: -0.14682927 | E7: -0.033321083 | F7: 0.0175 | G7: 0.060886918 | H7: 0.10661538
A8: Downside | B8: Free cash flow | C8: -256 | D8: -174.296 | E8: -64.865 | F8: 30.7 | G8: 174.76 | H8: 388.825
A9: Base | B9: Revenue | C9: 650 | D9: 1240 | E9: 2050 | F9: 3000 | G9: 4100 | H9: 5250
A10: Base | B10: Gross margin | C10: 0.46 | D10: 0.58 | E10: 0.66 | F10: 0.71 | G10: 0.74 | H10: 0.76
A11: Base | B11: Adjusted operating margin | C11: -0.35538462 | D11: -0.016774194 | E11: 0.14292683 | F11: 0.22 | G11: 0.26926829 | H11: 0.30857143
A12: Base | B12: Free cash flow | C12: -256 | D12: -45.8 | E12: 278 | F12: 655 | G12: 1114 | H12: 1645
A13: Upside | B13: Revenue | C13: 650 | D13: 1388.8 | E13: 2501 | F13: 3900 | G13: 5576 | H13: 7350
A14: Upside | B14: Gross margin | C14: 0.46 | D14: 0.61 | E14: 0.71 | F14: 0.77 | G14: 0.8 | H14: 0.82
A15: Upside | B15: Adjusted operating margin | C15: -0.35538462 | D15: 0.034539171 | E15: 0.22683327 | F15: 0.32523077 | G15: 0.38464849 | H15: 0.43306122
A16: Upside | B16: Free cash flow | C16: -256 | D16: 22.968 | E16: 552.31 | F16: 1263.4 | G16: 2154.8 | H16: 3208

Sheet Use of Proceeds
A1: Use of Proceeds
A2: Allocation of $800M primary capital. The $200M secondary component is excluded.
A4: Category | B4: Amount ($M) | C4: % of primary | D4: Milestone | E4: Evidence
A5: Model training and infrastructure | B5: 220 | C5: 0.275 | D5: Train Replit models and cut compute cost per successful build by 65% | E5: Est.
A6: Enterprise expansion | B6: 160 | C6: 0.2 | D6: Reach 4,200 enterprise customers and 94% gross retention | E6: Est.
A7: User growth | B7: 140 | C7: 0.175 | D7: Reach 100M registered users and 5M paid individuals | E7: Est.
A8: International expansion | B8: 120 | C8: 0.15 | D8: Add local infrastructure, sales, and compliance in Europe, India, and the Middle East | E8: Est.
A9: Talent and research | B9: 120 | C9: 0.15 | D9: Hire model, security, enterprise, and international leaders | E9: Est.
A10: Execution reserve | B10: 40 | C10: 0.05 | D10: Keep at least $250M of operating cash | E10: Est.
A11: Total primary | B11: 800 | C11: 1 | D11: Fully allocated | E11: Derived

Sheet Valuation
A1: Valuation
A2: Illustrative forward-revenue framework. This is not a fairness opinion or investment recommendation.
A4: Entry metric | B4: Value | C4: Units
A5: Pre-money valuation | B5: 20000 | C5: $M
A6: Post-money valuation | B6: 20800 | C6: $M
A7: 2027 revenue | B7: 1240 | C7: $M
A8: Pre-money / NTM revenue | B8: 16.129032 | C8: x
A9: Post-money / NTM revenue | B9: 16.774194 | C9: x
A12: Exit revenue multiple | B12: 2030 revenue | C12: Implied equity value | D12: Gross MOIC
A13: 6 | B13: 4100 | C13: 24600 | D13: 1.1826923
A14: 8 | B14: 4100 | C14: 32800 | D14: 1.5769231
A15: 10 | B15: 4100 | C15: 41000 | D15: 1.9711538
A16: 12 | B16: 4100 | C16: 49200 | D16: 2.3653846
A20: Comparable | B20: Revenue multiple | C20: Basis | D20: Source ID | E20: Caveat
A21: Salesforce | B21: 4.5 | C21: Forward P/S | D21: COMP-CRM-2026 | E21: Public market
A22: Atlassian | B22: 7.5 | C22: Market cap / LTM revenue | D22: COMP-TEAM-2026 | E22: Public proxy
A23: GitLab | B23: 7.7 | C23: Market cap / LTM revenue | D23: COMP-GTLB-2026 | E23: Public proxy
A24: ServiceNow | B24: 8.5 | C24: Forward P/S | D24: COMP-NOW-2026 | E24: Public market
A25: Microsoft | B25: 11.4 | C25: Market cap / LTM revenue | D25: COMP-MSFT-2026 | E25: Public proxy
A26: Replit Series E | B26: 16.129032 | C26: Pre-money / 2027E revenue | D26: MODEL-ESTIMATES | E26: Illustrative entry
A27: Cursor | B27: 29.3 | C27: Valuation / annualized revenue | D27: CURSOR-D-2025 | E27: Private-company disclosure
A28: Cloudflare | B28: 40.4 | C28: Market cap / LTM revenue | D28: COMP-NET-2026 | E28: High-growth public proxy

Sheet Slide Reconciliation
A1: Slide Reconciliation
A2: Headline metrics used in the presentation, with evidence and workbook-cell lineage.
A4: Slide | B4: Metric | C4: Deck display | D4: Model value | E4: Units | F4: Evidence class | G4: Source IDs | H4: Workbook reference | I4: Status
A5: 2 | B5: Post-money valuation | C5: $20.8B | D5: 20800 | E5: $M | F5: derived | G5: MODEL-ESTIMATES | H5: 'Read Me'!$B$21 | I5: Linked
A6: 2 | B6: Pre-money / 2027E revenue | C6: 16.1x | D6: 16.129032 | E6: x | F6: derived | G6: MODEL-ESTIMATES | H6: 'Valuation'!$B$8 | I6: Linked
A7: 2 | B7: Pre-money valuation | C7: $20.0B | D7: 20000 | E7: $M | F7: estimate | G7: MODEL-ESTIMATES | H7: 'Read Me'!$B$20 | I7: Linked
A8: 2 | B8: Primary capital | C8: $800M | D8: 800 | E8: $M | F8: estimate | G8: MODEL-ESTIMATES | H8: 'Read Me'!$B$18 | I8: Linked
A9: 2 | B9: Primary dilution | C9: 3.8% | D9: 0.038461538 | E9: % | F9: derived | G9: MODEL-ESTIMATES | H9: 'Read Me'!$B$22 | I9: Linked
A10: 2 | B10: Secondary liquidity | C10: $200M | D10: 200 | E10: $M | F10: estimate | G10: MODEL-ESTIMATES | H10: 'Read Me'!$B$19 | I10: Linked
A11: 2 | B11: Total buyer ownership | C11: 4.8% | D11: 0.048076923 | E11: % | F11: derived | G11: MODEL-ESTIMATES | H11: 'Read Me'!$B$23 | I11: Linked
A12: 2 | B12: Total raise | C12: $1.0B | D12: 1000 | E12: $M | F12: estimate | G12: MODEL-ESTIMATES | H12: 'Read Me'!$B$17 | I12: Linked
A13: 4 | B13: 2026 revenue | C13: $650M | D13: 650 | E13: $M | F13: estimate | G13: MODEL-ESTIMATES | H13: 'Revenue Build'!$E$8 | I13: Linked
A14: 4 | B14: Countries reached | C14: 190+ | D14: 190 | E14: # | F14: estimate | G14: MODEL-ESTIMATES | H14: 'Assumptions'!$B$203 | I14: Linked
A15: 4 | B15: Enterprise customers | C15: 1,200 | D15: 1200 | E15: # | F15: estimate | G15: MODEL-ESTIMATES | H15: 'Historical KPIs'!$F$10 | I15: Linked
A16: 4 | B16: Exit ARR target | C16: $1.0B | D16: 1000 | E16: $M | F16: management_target | G16: RPL-D-2026 | H16: 'Historical KPIs'!$F$6 | I16: Linked
... A25: 9 | B25: UKG feedback-capacity gain | C25: 400% | D25: 4 | E25: x | F25: public | G25: RPL-CUST-UKG | H25: 'Assumptions'!$B$201 | I25: Linked
A26: 11 | B26: 2031 revenue / TAM | C26: 2.1% | D26: 0.021 | E26: % | F26: derived | G26: MODEL-ESTIMATES | I26: Source-only
A27: 11 | B27: Near-term SAM | C27: $90B | D27: 90000 | E27: $M | F27: derived | G27: MODEL-ESTIMATES | H27: 'Market Model'!$E$9 | I27: Linked
A28: 11 | B28: TAM | C28: $250B | D28: 250000 | E28: $M | F28: derived | G28: MODEL-ESTIMATES | H28: 'Market Model'!$D$9 | I28: Linked
A29: 15 | B29: 2026 revenue | C29: $650M | D29: 650 | E29: $M | F29: estimate | G29: MODEL-ESTIMATES | H29: 'Revenue Build'!$E$8 | I29: Linked
A30: 15 | B30: 2028 adjusted operating income | C30: $293M | D30: 293 | E30: $M | F30: estimate | G30: MODEL-ESTIMATES | H30: 'P&L'!$E$13 | I30: Linked
A31: 15 | B31: 2028 free cash flow | C31: $278M | D31: 278 | E31: $M | F31: estimate | G31: MODEL-ESTIMATES | H31: 'Cash Flow'!$E$10 | I31: Linked
A32: 15 | B32: 2031 adjusted operating margin | C32: 31% | D32: 0.30857143 | E32: % | F32: estimate | G32: MODEL-ESTIMATES | H32: 'P&L'!$H$14 | I32: Linked
A33: 16 | B33: 2026 to 2031 revenue CAGR | C33: 52% | D33: 0.51862026 | E33: % | F33: derived | G33: MODEL-ESTIMATES | I33: Source-only
A34: 16 | B34: 2031 enterprise + runtime mix | C34: 77% | D34: 0.77142857 | E34: % | F34: derived | G34: MODEL-ESTIMATES | I34: Source-only
A35: 16 | B35: 2031 gross margin | C35: 76% | D35: 0.76 | E35: % | F35: estimate | G35: MODEL-ESTIMATES | H35: 'P&L'!$H$9 | I35: Linked
A36: 16 | B36: 2031 international mix | C36: 52% | D36: 0.52 | E36: % | F36: estimate | G36: MODEL-ESTIMATES | H36: 'Assumptions'!$B$171 | I36: Linked
A37: 16 | B37: 2031 revenue | C37: $5.25B | D37: 5250 | E37: $M | F37: estimate | G37: MODEL-ESTIMATES | H37: 'Revenue Build'!$J$8 | I37: Linked
A38: 17 | B38: Enterprise GRR | C38: 92% | D38: 0.92 | E38: % | F38: estimate | G38: MODEL-ESTIMATES | H38: 'Historical KPIs'!$F$12 | I38: Linked
A39: 17 | B39: Enterprise NRR | C39: 138% | D39: 1.38 | E39: % | F39: estimate | G39: MODEL-ESTIMATES | H39: 'Historical KPIs'!$F$13 | I39: Linked
A40: 18 | B40: 2026 gross margin | C40: 46% | D40: 0.46 | E40: % | F40: estimate | G40: MODEL-ESTIMATES | H40: 'P&L'!$C$9 | I40: Linked
A41: 18 | B41: Enterprise CAC payback | C41: 14 mo. | D41: 14 | E41: months | F41: estimate | G41: MODEL-ESTIMATES | H41: 'Unit Economics'!$C$9 | I41: Linked
A42: 18 | B42: Enterprise LTV / CAC | C42: 4.2x | D42: 4.2 | E42: x | F42: estimate | G42: MODEL-ESTIMATES | H42: 'Unit Economics'!$C$10 | I42: Linked
A43: 18 | B43: Individual CAC payback | C43: 6 mo. | D43: 6 | E43: months | F43: estimate | G43: MODEL-ESTIMATES | H43: 'Unit Economics'!$C$7 | I43: Linked
A44: 19 | B44: 2028 free cash flow | C44: $278M | D44: 278 | E44: $M | F44: estimate | G44: MODEL-ESTIMATES | H44: 'Cash Flow'!$E$10 | I44: Linked
A45: 20 | B45: Enterprise expansion | C45: $160M | D45: 160 | E45: $M | F45: estimate | G45: MODEL-ESTIMATES | H45: 'Use of Proceeds'!$B$6 | I45: Linked
A46: 20 | B46: Execution reserve | C46: $40M | D46: 40 | E46: $M | F46: estimate | G46: MODEL-ESTIMATES | H46: 'Use of Proceeds'!$B$10 | I46: Linked
... A54: 21 | B54: Downside cash at IPO | C54: $902M | D54: 902.209 | E54: $M | F54: derived | G54: MODEL-ESTIMATES | H54: 'Cash Flow'!$B$27 | I54: Linked
A55: 21 | B55: Further equity before IPO | C55: None | D55: None before IPO in the base case | E55: text | F55: derived | G55: MODEL-ESTIMATES | H55: 'Cash Flow'!$B$28 | I55: Linked
A56: 21 | B56: IPO target | C56: H2 2030 | D56: 47756 | E56: date | F56: estimate | G56: MODEL-ESTIMATES | H56: 'Cash Flow'!$B$25 | I56: Linked
...

Sheet QA Checks
A1: QA Checks
A2: Build-time controls. PASS is required before the materials are considered final.
A4: Check | B4: Observed | C4: Expected / comparator | D4: Status
A5: Transaction sources = uses | B5: 1000 | C5: 1000 | D5: PASS
A6: Post-money valuation | B6: 20800 | C6: 20800 | D6: PASS
A7: Primary capital fully allocated | B7: 800 | C7: 800 | D7: PASS
A8: TAM components sum | B8: 250000 | C8: 250000 | D8: PASS
A9: All public sources have URLs | B9: 35 | C9: 35 | D9: PASS
A10: Downside < base < upside revenue in 2031 | B10: 3412.5 | C10: 7350 | D10: PASS
A11: Base free cash flow positive by 2028 | B11: 278 | C11: 0 | D11: PASS
A12: Series E primary included once | B12: 800 | C12: 800 | D12: PASS
A13: No-financing cash falls below minimum | B13: 46356 | C13: 46356 | D13: PASS
A14: Base cash remains above minimum | B14: 252.26667 | C14: 250 | D14: PASS
A15: Downside cash remains above minimum | B15: 252.26667 | C15: 250 | D15: PASS
